<?xml version="1.0" ?>
<!-- =================================================================================== -->
<!-- |    This document was autogenerated by xacro from src/openarmx_description/urdf/robot/v10.urdf.xacro | -->
<!-- |    EDITING THIS FILE BY HAND IS NOT RECOMMENDED                                 | -->
<!-- =================================================================================== -->
<robot name="openarmx">
  <!-- <xacro:arg name="right_arm_base_xyz" default="0.0 -0.031 0.698" />
  <xacro:arg name="right_arm_base_rpy" default="1.5708 0 0" />

  <xacro:arg name="left_arm_base_xyz" default="0.0 0.031 0.698" />
  <xacro:arg name="left_arm_base_rpy" default="-1.5708 0 0" /> -->
  <!-- Is the robot being simulated in gazebo? -->
  <!-- <xacro:arg name="gazebo" default="false" /> -->
  <link name="world"/>
  <joint name="openarmx_body_world_joint" type="fixed">
    <parent link="world"/>
    <child link="openarmx_body_link0"/>
    <origin rpy="0 0 0" xyz="0 0 0"/>
  </joint>
  <link name="openarmx_body_link0">
    <visual name="openarmx_body_link0_visual">
      <origin rpy="0.0 0.0 0.0" xyz="0.0 0.0 0.0"/>
      <geometry>
        <mesh filename="package://openarmx_description/meshes/body/v10/visual/body_link0.dae" scale="1.0 1.0 1.0"/>
      </geometry>
    </visual>
    <collision name="openarmx_body_link0_collision">
      <origin rpy="0.0 0.0 0.0" xyz="0.0 0.0 0.0"/>
      <geometry>
        <mesh filename="package://openarmx_description/meshes/body/v10/collision/body_link0_symp.stl" scale="0.001 0.001 0.001"/>
      </geometry>
    </collision>
    <inertial>
      <origin rpy="0.0 0.0 0.0" xyz="0.0 0.0 0.0"/>
      <mass value="13.89"/>
      <inertia ixx="1.653" ixy="0.0" ixz="0.0" iyy="1.653" iyz="0.0" izz="0.051"/>
    </inertial>
  </link>
  <joint name="openarmx_left_openarmx_body_link0_joint" type="fixed">
    <parent link="openarmx_body_link0"/>
    <child link="openarmx_left_link0"/>
    <origin rpy="-1.5708 0 0" xyz="0.0 0.031 0.735"/>
  </joint>
  <link name="openarmx_left_link0">
    <visual name="openarmx_left_link0_visual">
      <origin rpy="0.0 0.0 0.0" xyz="0.0 0.0 0.0"/>
      <geometry>
        <!-- <mesh filename="package://${description_pkg}/meshes/arm/${arm_type}/visual/${name}.dae" scale="0.001 ${0.001*reflect} 0.001" /> -->
        <mesh filename="package://openarmx_description/meshes/arm/v10/visual/link0.dae" scale="1.0 -1.0 1.0"/>
      </geometry>
    </visual>
    <collision name="openarmx_left_link0_collision">
      <origin rpy="0.0 0.0 0.0" xyz="0.0 0.0 0.0"/>
      <geometry>
        <!-- <mesh filename="package://openarmx_description/meshes/arm/${arm_type}/collision/${name}.stl" scale="0.001 0.001 0.001" /> -->
        <mesh filename="package://openarmx_description/meshes/arm/v10/collision/link0_symp.stl" scale="1.0 -1.0 1.0"/>
      </geometry>
    </collision>
    <inertial>
      <origin rpy="0.0 0.0 0.0" xyz="0.000319 -0.00067 0.029184"/>
      <mass value="1.77268"/>
      <inertia ixx="0.002463" ixy="2.7e-05" ixz="1.8e-05" iyy="0.001962" iyz="3.6e-05" izz="0.003414"/>
    </inertial>
  </link>
  <link name="openarmx_left_link1">
    <visual name="openarmx_left_link1_visual">
      <origin rpy="0.0 0.0 0.0" xyz="0.0 0.0 0.0"/>
      <geometry>
        <!-- <mesh filename="package://${description_pkg}/meshes/arm/${arm_type}/visual/${name}.dae" scale="0.001 ${0.001*reflect} 0.001" /> -->
        <mesh filename="package://openarmx_description/meshes/arm/v10/visual/link1.dae" scale="1.0 -1.0 1.0"/>
      </geometry>
    </visual>
    <collision name="openarmx_left_link1_collision">
      <origin rpy="0.0 0.0 0.0" xyz="0.0 0.0 0.0"/>
      <geometry>
        <!-- <mesh filename="package://openarmx_description/meshes/arm/${arm_type}/collision/${name}.stl" scale="0.001 0.001 0.001" /> -->
        <mesh filename="package://openarmx_description/meshes/arm/v10/collision/link1_symp.stl" scale="1.0 -1.0 1.0"/>
      </geometry>
    </collision>
    <inertial>
      <origin rpy="0.0 0.0 0.0" xyz="0.004452 2.5e-05 0.073323"/>
      <mass value="1.688763"/>
      <inertia ixx="0.003463" ixy="2e-06" ixz="9.8e-05" iyy="0.002551" iyz="1e-06" izz="0.001916"/>
    </inertial>
  </link>
  <joint name="openarmx_left_joint1" type="revolute">
    <origin rpy="-0.0 -0.0 -0.0" xyz="0.0 0.0 0.058"/>
    <parent link="openarmx_left_link0"/>
    <child link="openarmx_left_link1"/>
    <axis xyz="0 0 1"/>
    <limit effort="120" lower="-3.344396" upper="0.9056039999999999" velocity="10.47"/>
  </joint>
  <link name="openarmx_left_link2">
    <visual name="openarmx_left_link2_visual">
      <origin rpy="0.0 0.0 0.0" xyz="0.0 0.0 0.0"/>
      <geometry>
        <!-- <mesh filename="package://${description_pkg}/meshes/arm/${arm_type}/visual/${name}.dae" scale="0.001 ${0.001*reflect} 0.001" /> -->
        <mesh filename="package://openarmx_description/meshes/arm/v10/visual/link2.dae" scale="1.0 -1.0 1.0"/>
      </geometry>
    </visual>
    <collision name="openarmx_left_link2_collision">
      <origin rpy="0.0 0.0 0.0" xyz="0.0 0.0 0.0"/>
      <geometry>
        <!-- <mesh filename="package://openarmx_description/meshes/arm/${arm_type}/collision/${name}.stl" scale="0.001 0.001 0.001" /> -->
        <mesh filename="package://openarmx_description/meshes/arm/v10/collision/link2_symp.stl" scale="1.0 -1.0 1.0"/>
      </geometry>
    </collision>
    <inertial>
      <origin rpy="0.0 0.0 0.0" xyz="-0.003787 -0.000221 0.04901"/>
      <mass value="0.396704"/>
      <inertia ixx="0.000834" ixy="-1e-06" ixz="0.00017" iyy="0.000822" iyz="-5e-06" izz="0.000385"/>
    </inertial>
  </link>
  <joint name="openarmx_left_joint2" type="revolute">
    <origin rpy="-1.5708 -0.0 -0.0" xyz="-0.0205 0.0 0.081"/>
    <parent link="openarmx_left_link1"/>
    <child link="openarmx_left_link2"/>
    <axis xyz="-1 0 0"/>
    <limit effort="120" lower="-3.2707963267948967" upper="0.1292036732051034" velocity="10.47"/>
  </joint>
  <link name="openarmx_left_link3">
    <visual name="openarmx_left_link3_visual">
      <origin rpy="0.0 0.0 0.0" xyz="0.0 0.0 0.0"/>
      <geometry>
        <!-- <mesh filename="package://${description_pkg}/meshes/arm/${arm_type}/visual/${name}.dae" scale="0.001 ${0.001*reflect} 0.001" /> -->
        <mesh filename="package://openarmx_description/meshes/arm/v10/visual/link3.dae" scale="1.0 -1.0 1.0"/>
      </geometry>
    </visual>
    <collision name="openarmx_left_link3_collision">
      <origin rpy="0.0 0.0 0.0" xyz="0.0 0.0 0.0"/>
      <geometry>
        <!-- <mesh filename="package://openarmx_description/meshes/arm/${arm_type}/collision/${name}.stl" scale="0.001 0.001 0.001" /> -->
        <mesh filename="package://openarmx_description/meshes/arm/v10/collision/link3_symp.stl" scale="1.0 -1.0 1.0"/>
      </geometry>
    </collision>
    <inertial>
      <origin rpy="0.0 0.0 0.0" xyz="-0.000828 -0.000236 0.083336"/>
      <mass value="2.492784"/>
      <inertia ixx="0.010352" ixy="-1.5e-05" ixz="-3.4e-05" iyy="0.010343" iyz="9.4e-05" izz="0.003003"/>
    </inertial>
  </link>
  <joint name="openarmx_left_joint3" type="revolute">
    <origin rpy="0.0 0.0 0.0" xyz="0.02 0.0 0.099"/>
    <parent link="openarmx_left_link2"/>
    <child link="openarmx_left_link3"/>
    <axis xyz="0 0 1"/>
    <limit effort="60" lower="-1.57" upper="1.57" velocity="10.47"/>
  </joint>
  <link name="openarmx_left_link4">
    <visual name="openarmx_left_link4_visual">
      <origin rpy="0.0 0.0 0.0" xyz="0.0 0.0 0.0"/>
      <geometry>
        <!-- <mesh filename="package://${description_pkg}/meshes/arm/${arm_type}/visual/${name}.dae" scale="0.001 ${0.001*reflect} 0.001" /> -->
        <mesh filename="package://openarmx_description/meshes/arm/v10/visual/link4.dae" scale="1.0 1.0 1.0"/>
      </geometry>
    </visual>
    <collision name="openarmx_left_link4_collision">
      <origin rpy="0.0 0.0 0.0" xyz="0.0 0.0 0.0"/>
      <geometry>
        <!-- <mesh filename="package://openarmx_description/meshes/arm/${arm_type}/collision/${name}.stl" scale="0.001 0.001 0.001" /> -->
        <mesh filename="package://openarmx_description/meshes/arm/v10/collision/link4_symp.stl" scale="1.0 1.0 1.0"/>
      </geometry>
    </collision>
    <inertial>
      <origin rpy="0.0 0.0 0.0" xyz="-0.002591 -0.030135 0.07147"/>
      <mass value="0.779755"/>
      <inertia ixx="0.002015" ixy="0.0" ixz="2.3e-05" iyy="0.00162" iyz="-4e-05" izz="0.000768"/>
    </inertial>
  </link>
  <joint name="openarmx_left_joint4" type="revolute">
    <origin rpy="0.0 0.0 0.0" xyz="0.0 0.031002 0.14181"/>
    <parent link="openarmx_left_link3"/>
    <child link="openarmx_left_link4"/>
    <axis xyz="0 1 0"/>
    <limit effort="60" lower="0.0" upper="1.8" velocity="10.47"/>
  </joint>
  <link name="openarmx_left_link4_ext"/>
  <joint name="openarmx_left_joint4_ext" type="fixed">
    <origin rpy="0.0 0.0 0.0" xyz="0.0 -0.065 0.0"/>
    <parent link="openarmx_left_link4"/>
    <child link="openarmx_left_link4_ext"/>
  </joint>
  <link name="openarmx_left_link5">
    <visual name="openarmx_left_link5_visual">
      <origin rpy="0.0 0.0 0.0" xyz="0.0 0.0 0.0"/>
      <geometry>
        <!-- <mesh filename="package://${description_pkg}/meshes/arm/${arm_type}/visual/${name}.dae" scale="0.001 ${0.001*reflect} 0.001" /> -->
        <mesh filename="package://openarmx_description/meshes/arm/v10/visual/link5.dae" scale="1.0 -1.0 1.0"/>
      </geometry>
    </visual>
    <collision name="openarmx_left_link5_collision">
      <origin rpy="0.0 0.0 0.0" xyz="0.0 0.0 0.0"/>
      <geometry>
        <!-- <mesh filename="package://openarmx_description/meshes/arm/${arm_type}/collision/${name}.stl" scale="0.001 0.001 0.001" /> -->
        <mesh filename="package://openarmx_description/meshes/arm/v10/collision/link5_symp.stl" scale="1.0 -1.0 1.0"/>
      </geometry>
    </collision>
    <inertial>
      <origin rpy="0.0 0.0 0.0" xyz="-0.002256 -0.000305 0.0533"/>
      <mass value="0.687255"/>
      <inertia ixx="0.000831" ixy="5e-06" ixz="1.1e-05" iyy="0.001066" iyz="-1e-06" izz="0.000496"/>
    </inertial>
  </link>
  <joint name="openarmx_left_joint5" type="revolute">
    <origin rpy="0.0 0.0 0.0" xyz="0.0 -0.0309 0.126"/>
    <parent link="openarmx_left_link4"/>
    <child link="openarmx_left_link5"/>
    <axis xyz="0 0 1"/>
    <limit effort="14" lower="-1.5" upper="1.5" velocity="10.47"/>
  </joint>
  <link name="openarmx_left_link6">
    <visual name="openarmx_left_link6_visual">
      <origin rpy="0.0 0.0 0.0" xyz="0.0 0.0 0.0"/>
      <geometry>
        <!-- <mesh filename="package://${description_pkg}/meshes/arm/${arm_type}/visual/${name}.dae" scale="0.001 ${0.001*reflect} 0.001" /> -->
        <mesh filename="package://openarmx_description/meshes/arm/v10/visual/link6.dae" scale="1.0 -1.0 1.0"/>
      </geometry>
    </visual>
    <collision name="openarmx_left_link6_collision">
      <origin rpy="0.0 0.0 0.0" xyz="0.0 0.0 0.0"/>
      <geometry>
        <!-- <mesh filename="package://openarmx_description/meshes/arm/${arm_type}/collision/${name}.stl" scale="0.001 0.001 0.001" /> -->
        <mesh filename="package://openarmx_description/meshes/arm/v10/collision/link6_symp.stl" scale="1.0 -1.0 1.0"/>
      </geometry>
    </collision>
    <inertial>
      <origin rpy="0.0 0.0 0.0" xyz="-0.03564 0.005114 -0.003582"/>
      <mass value="0.384836"/>
      <inertia ixx="0.000292" ixy="-1.7e-05" ixz="-3.2e-05" iyy="0.000276" iyz="1.8e-05" izz="0.000227"/>
    </inertial>
  </link>
  <joint name="openarmx_left_joint6" type="revolute">
    <origin rpy="0.0 0.0 0.0" xyz="0.037426 0.0 0.131"/>
    <parent link="openarmx_left_link5"/>
    <child link="openarmx_left_link6"/>
    <axis xyz="1 0 0"/>
    <limit effort="14" lower="-0.75" upper="0.75" velocity="10.47"/>
  </joint>
  <link name="openarmx_left_link7">
    <visual name="openarmx_left_link7_visual">
      <origin rpy="0.0 0.0 0.0" xyz="0.0 0.0 0.0"/>
      <geometry>
        <!-- <mesh filename="package://${description_pkg}/meshes/arm/${arm_type}/visual/${name}.dae" scale="0.001 ${0.001*reflect} 0.001" /> -->
        <mesh filename="package://openarmx_description/meshes/arm/v10/visual/link7.dae" scale="1.0 -1.0 1.0"/>
      </geometry>
    </visual>
    <collision name="openarmx_left_link7_collision">
      <origin rpy="0.0 0.0 0.0" xyz="0.0 0.0 0.0"/>
      <geometry>
        <!-- <mesh filename="package://openarmx_description/meshes/arm/${arm_type}/collision/${name}.stl" scale="0.001 0.001 0.001" /> -->
        <mesh filename="package://openarmx_description/meshes/arm/v10/collision/link7_symp.stl" scale="1.0 -1.0 1.0"/>
      </geometry>
    </collision>
    <inertial>
      <origin rpy="0.0 0.0 0.0" xyz="-3e-06 -0.002128 0.091961"/>
      <mass value="0.624972"/>
      <inertia ixx="0.001598" ixy="-5e-05" ixz="0.0" iyy="0.001067" iyz="-8.7e-05" izz="0.000784"/>
    </inertial>
  </link>
  <joint name="openarmx_left_joint7" type="revolute">
    <origin rpy="0.0 0.0 0.0" xyz="-0.0375 0.0 0.0"/>
    <parent link="openarmx_left_link6"/>
    <child link="openarmx_left_link7"/>
    <axis xyz="0 -1 0"/>
    <limit effort="14" lower="-1.4" upper="1.4" velocity="10.47"/>
  </joint>
  <link name="openarmx_left_link7_pico"/>
  <joint name="openarmx_left_link7_pico_joint" type="fixed">
    <origin rpy="0 3.1416 4.7124" xyz="0 0 0"/>
    <parent link="openarmx_left_link7"/>
    <child link="openarmx_left_link7_pico"/>
  </joint>
  <!-- <link name="${prefix}link8"/>

    <joint name="${prefix}joint8" type="fixed">
      <xacro:openarmx-kinematics name="joint8" config="${kinematics}" />
      <parent link="${prefix}link7" />
      <child link="${prefix}link8" />
    </joint> -->
  <joint name="openarmx_right_openarmx_body_link0_joint" type="fixed">
    <parent link="openarmx_body_link0"/>
    <child link="openarmx_right_link0"/>
    <origin rpy="1.5708 0 0" xyz="0.0 -0.031 0.735"/>
  </joint>
  <link name="openarmx_right_link0">
    <visual name="openarmx_right_link0_visual">
      <origin rpy="0.0 0.0 0.0" xyz="0.0 0.0 0.0"/>
      <geometry>
        <!-- <mesh filename="package://${description_pkg}/meshes/arm/${arm_type}/visual/${name}.dae" scale="0.001 ${0.001*reflect} 0.001" /> -->
        <mesh filename="package://openarmx_description/meshes/arm/v10/visual/link0.dae" scale="1.0 1.0 1.0"/>
      </geometry>
    </visual>
    <collision name="openarmx_right_link0_collision">
      <origin rpy="0.0 0.0 0.0" xyz="0.0 0.0 0.0"/>
      <geometry>
        <!-- <mesh filename="package://openarmx_description/meshes/arm/${arm_type}/collision/${name}.stl" scale="0.001 0.001 0.001" /> -->
        <mesh filename="package://openarmx_description/meshes/arm/v10/collision/link0_symp.stl" scale="1.0 1.0 1.0"/>
      </geometry>
    </collision>
    <inertial>
      <origin rpy="0.0 0.0 0.0" xyz="0.000319 0.00067 0.029184"/>
      <mass value="1.77268"/>
      <inertia ixx="0.002463" ixy="2.7e-05" ixz="1.8e-05" iyy="0.001962" iyz="3.6e-05" izz="0.003414"/>
    </inertial>
  </link>
  <link name="openarmx_right_link1">
    <visual name="openarmx_right_link1_visual">
      <origin rpy="0.0 0.0 0.0" xyz="0.0 0.0 0.0"/>
      <geometry>
        <!-- <mesh filename="package://${description_pkg}/meshes/arm/${arm_type}/visual/${name}.dae" scale="0.001 ${0.001*reflect} 0.001" /> -->
        <mesh filename="package://openarmx_description/meshes/arm/v10/visual/link1.dae" scale="1.0 1.0 1.0"/>
      </geometry>
    </visual>
    <collision name="openarmx_right_link1_collision">
      <origin rpy="0.0 0.0 0.0" xyz="0.0 0.0 0.0"/>
      <geometry>
        <!-- <mesh filename="package://openarmx_description/meshes/arm/${arm_type}/collision/${name}.stl" scale="0.001 0.001 0.001" /> -->
        <mesh filename="package://openarmx_description/meshes/arm/v10/collision/link1_symp.stl" scale="1.0 1.0 1.0"/>
      </geometry>
    </collision>
    <inertial>
      <origin rpy="0.0 0.0 0.0" xyz="0.004452 -2.5e-05 0.073323"/>
      <mass value="1.688763"/>
      <inertia ixx="0.003463" ixy="2e-06" ixz="9.8e-05" iyy="0.002551" iyz="1e-06" izz="0.001916"/>
    </inertial>
  </link>
  <joint name="openarmx_right_joint1" type="revolute">
    <origin rpy="0.0 0.0 0.0" xyz="0.0 0.0 0.058"/>
    <parent link="openarmx_right_link0"/>
    <child link="openarmx_right_link1"/>
    <axis xyz="0 0 1"/>
    <limit effort="120" lower="-1.25" upper="3.0" velocity="10.47"/>
  </joint>
  <link name="openarmx_right_link2">
    <visual name="openarmx_right_link2_visual">
      <origin rpy="0.0 0.0 0.0" xyz="0.0 0.0 0.0"/>
      <geometry>
        <!-- <mesh filename="package://${description_pkg}/meshes/arm/${arm_type}/visual/${name}.dae" scale="0.001 ${0.001*reflect} 0.001" /> -->
        <mesh filename="package://openarmx_description/meshes/arm/v10/visual/link2.dae" scale="1.0 1.0 1.0"/>
      </geometry>
    </visual>
    <collision name="openarmx_right_link2_collision">
      <origin rpy="0.0 0.0 0.0" xyz="0.0 0.0 0.0"/>
      <geometry>
        <!-- <mesh filename="package://openarmx_description/meshes/arm/${arm_type}/collision/${name}.stl" scale="0.001 0.001 0.001" /> -->
        <mesh filename="package://openarmx_description/meshes/arm/v10/collision/link2_symp.stl" scale="1.0 1.0 1.0"/>
      </geometry>
    </collision>
    <inertial>
      <origin rpy="0.0 0.0 0.0" xyz="-0.003787 0.000221 0.04901"/>
      <mass value="0.396704"/>
      <inertia ixx="0.000834" ixy="-1e-06" ixz="0.00017" iyy="0.000822" iyz="-5e-06" izz="0.000385"/>
    </inertial>
  </link>
  <joint name="openarmx_right_joint2" type="revolute">
    <origin rpy="1.5708 0.0 0.0" xyz="-0.0205 0.0 0.081"/>
    <parent link="openarmx_right_link1"/>
    <child link="openarmx_right_link2"/>
    <axis xyz="-1 0 0"/>
    <limit effort="120" lower="-0.1292036732051034" upper="3.2707963267948967" velocity="10.47"/>
  </joint>
  <link name="openarmx_right_link3">
    <visual name="openarmx_right_link3_visual">
      <origin rpy="0.0 0.0 0.0" xyz="0.0 0.0 0.0"/>
      <geometry>
        <!-- <mesh filename="package://${description_pkg}/meshes/arm/${arm_type}/visual/${name}.dae" scale="0.001 ${0.001*reflect} 0.001" /> -->
        <mesh filename="package://openarmx_description/meshes/arm/v10/visual/link3.dae" scale="1.0 1.0 1.0"/>
      </geometry>
    </visual>
    <collision name="openarmx_right_link3_collision">
      <origin rpy="0.0 0.0 0.0" xyz="0.0 0.0 0.0"/>
      <geometry>
        <!-- <mesh filename="package://openarmx_description/meshes/arm/${arm_type}/collision/${name}.stl" scale="0.001 0.001 0.001" /> -->
        <mesh filename="package://openarmx_description/meshes/arm/v10/collision/link3_symp.stl" scale="1.0 1.0 1.0"/>
      </geometry>
    </collision>
    <inertial>
      <origin rpy="0.0 0.0 0.0" xyz="-0.000828 0.000236 0.083336"/>
      <mass value="2.492784"/>
      <inertia ixx="0.010352" ixy="-1.5e-05" ixz="-3.4e-05" iyy="0.010343" iyz="9.4e-05" izz="0.003003"/>
    </inertial>
  </link>
  <joint name="openarmx_right_joint3" type="revolute">
    <origin rpy="0.0 0.0 0.0" xyz="0.02 0.0 0.099"/>
    <parent link="openarmx_right_link2"/>
    <child link="openarmx_right_link3"/>
    <axis xyz="0 0 1"/>
    <limit effort="60" lower="-1.57" upper="1.57" velocity="10.47"/>
  </joint>
  <link name="openarmx_right_link4">
    <visual name="openarmx_right_link4_visual">
      <origin rpy="0.0 0.0 0.0" xyz="0.0 0.0 0.0"/>
      <geometry>
        <!-- <mesh filename="package://${description_pkg}/meshes/arm/${arm_type}/visual/${name}.dae" scale="0.001 ${0.001*reflect} 0.001" /> -->
        <mesh filename="package://openarmx_description/meshes/arm/v10/visual/link4.dae" scale="1.0 1.0 1.0"/>
      </geometry>
    </visual>
    <collision name="openarmx_right_link4_collision">
      <origin rpy="0.0 0.0 0.0" xyz="0.0 0.0 0.0"/>
      <geometry>
        <!-- <mesh filename="package://openarmx_description/meshes/arm/${arm_type}/collision/${name}.stl" scale="0.001 0.001 0.001" /> -->
        <mesh filename="package://openarmx_description/meshes/arm/v10/collision/link4_symp.stl" scale="1.0 1.0 1.0"/>
      </geometry>
    </collision>
    <inertial>
      <origin rpy="0.0 0.0 0.0" xyz="-0.002591 -0.030135 0.07147"/>
      <mass value="0.779755"/>
      <inertia ixx="0.002015" ixy="0.0" ixz="2.3e-05" iyy="0.00162" iyz="-4e-05" izz="0.000768"/>
    </inertial>
  </link>
  <joint name="openarmx_right_joint4" type="revolute">
    <origin rpy="0.0 0.0 0.0" xyz="0.0 0.031002 0.14181"/>
    <parent link="openarmx_right_link3"/>
    <child link="openarmx_right_link4"/>
    <axis xyz="0 1 0"/>
    <limit effort="60" lower="0.0" upper="1.8" velocity="10.47"/>
  </joint>
  <link name="openarmx_right_link4_ext"/>
  <joint name="openarmx_right_joint4_ext" type="fixed">
    <origin rpy="0.0 0.0 0.0" xyz="0.0 0.0 0.0"/>
    <parent link="openarmx_right_link4"/>
    <child link="openarmx_right_link4_ext"/>
  </joint>
  <link name="openarmx_right_link5">
    <visual name="openarmx_right_link5_visual">
      <origin rpy="0.0 0.0 0.0" xyz="0.0 0.0 0.0"/>
      <geometry>
        <!-- <mesh filename="package://${description_pkg}/meshes/arm/${arm_type}/visual/${name}.dae" scale="0.001 ${0.001*reflect} 0.001" /> -->
        <mesh filename="package://openarmx_description/meshes/arm/v10/visual/link5.dae" scale="1.0 1.0 1.0"/>
      </geometry>
    </visual>
    <collision name="openarmx_right_link5_collision">
      <origin rpy="0.0 0.0 0.0" xyz="0.0 0.0 0.0"/>
      <geometry>
        <!-- <mesh filename="package://openarmx_description/meshes/arm/${arm_type}/collision/${name}.stl" scale="0.001 0.001 0.001" /> -->
        <mesh filename="package://openarmx_description/meshes/arm/v10/collision/link5_symp.stl" scale="1.0 1.0 1.0"/>
      </geometry>
    </collision>
    <inertial>
      <origin rpy="0.0 0.0 0.0" xyz="-0.002256 0.000305 0.0533"/>
      <mass value="0.687255"/>
      <inertia ixx="0.000831" ixy="5e-06" ixz="1.1e-05" iyy="0.001066" iyz="-1e-06" izz="0.000496"/>
    </inertial>
  </link>
  <joint name="openarmx_right_joint5" type="revolute">
    <origin rpy="0.0 0.0 0.0" xyz="0.0 -0.0309 0.126"/>
    <parent link="openarmx_right_link4"/>
    <child link="openarmx_right_link5"/>
    <axis xyz="0 0 1"/>
    <limit effort="14" lower="-1.5" upper="1.5" velocity="10.47"/>
  </joint>
  <link name="openarmx_right_link6">
    <visual name="openarmx_right_link6_visual">
      <origin rpy="0.0 0.0 0.0" xyz="0.0 0.0 0.0"/>
      <geometry>
        <!-- <mesh filename="package://${description_pkg}/meshes/arm/${arm_type}/visual/${name}.dae" scale="0.001 ${0.001*reflect} 0.001" /> -->
        <mesh filename="package://openarmx_description/meshes/arm/v10/visual/link6.dae" scale="1.0 1.0 1.0"/>
      </geometry>
    </visual>
    <collision name="openarmx_right_link6_collision">
      <origin rpy="0.0 0.0 0.0" xyz="0.0 0.0 0.0"/>
      <geometry>
        <!-- <mesh filename="package://openarmx_description/meshes/arm/${arm_type}/collision/${name}.stl" scale="0.001 0.001 0.001" /> -->
        <mesh filename="package://openarmx_description/meshes/arm/v10/collision/link6_symp.stl" scale="1.0 1.0 1.0"/>
      </geometry>
    </collision>
    <inertial>
      <origin rpy="0.0 0.0 0.0" xyz="-0.03564 -0.005114 -0.003582"/>
      <mass value="0.384836"/>
      <inertia ixx="0.000292" ixy="-1.7e-05" ixz="-3.2e-05" iyy="0.000276" iyz="1.8e-05" izz="0.000227"/>
    </inertial>
  </link>
  <joint name="openarmx_right_joint6" type="revolute">
    <origin rpy="0.0 0.0 0.0" xyz="0.037426 0.0 0.131"/>
    <parent link="openarmx_right_link5"/>
    <child link="openarmx_right_link6"/>
    <axis xyz="1 0 0"/>
    <limit effort="14" lower="-0.75" upper="0.75" velocity="10.47"/>
  </joint>
  <link name="openarmx_right_link7">
    <visual name="openarmx_right_link7_visual">
      <origin rpy="0.0 0.0 0.0" xyz="0.0 0.0 0.0"/>
      <geometry>
        <!-- <mesh filename="package://${description_pkg}/meshes/arm/${arm_type}/visual/${name}.dae" scale="0.001 ${0.001*reflect} 0.001" /> -->
        <mesh filename="package://openarmx_description/meshes/arm/v10/visual/link7.dae" scale="1.0 1.0 1.0"/>
      </geometry>
    </visual>
    <collision name="openarmx_right_link7_collision">
      <origin rpy="0.0 0.0 0.0" xyz="0.0 0.0 0.0"/>
      <geometry>
        <!-- <mesh filename="package://openarmx_description/meshes/arm/${arm_type}/collision/${name}.stl" scale="0.001 0.001 0.001" /> -->
        <mesh filename="package://openarmx_description/meshes/arm/v10/collision/link7_symp.stl" scale="1.0 1.0 1.0"/>
      </geometry>
    </collision>
    <inertial>
      <origin rpy="0.0 0.0 0.0" xyz="-3e-06 0.002128 0.091961"/>
      <mass value="0.624972"/>
      <inertia ixx="0.001598" ixy="-5e-05" ixz="0.0" iyy="0.001067" iyz="-8.7e-05" izz="0.000784"/>
    </inertial>
  </link>
  <joint name="openarmx_right_joint7" type="revolute">
    <origin rpy="0.0 0.0 0.0" xyz="-0.0375 0.0 0.0"/>
    <parent link="openarmx_right_link6"/>
    <child link="openarmx_right_link7"/>
    <axis xyz="0 1 0"/>
    <limit effort="14" lower="-1.4" upper="1.4" velocity="10.47"/>
  </joint>
  <link name="openarmx_right_link7_pico"/>
  <joint name="openarmx_right_link7_pico_joint" type="fixed">
    <origin rpy="0 3.1416 4.7124" xyz="0 0 0"/>
    <parent link="openarmx_right_link7"/>
    <child link="openarmx_right_link7_pico"/>
  </joint>
  <!-- <link name="${prefix}link8"/>

    <joint name="${prefix}joint8" type="fixed">
      <xacro:openarmx-kinematics name="joint8" config="${kinematics}" />
      <parent link="${prefix}link7" />
      <child link="${prefix}link8" />
    </joint> -->
  <link name="openarmx_left_hand">
    <visual name="openarmx_left_hand_visual">
      <origin rpy="0.0 0.0 0.0" xyz="0.0 0.0 -0.6585"/>
      <geometry>
        <mesh filename="package://openarmx_description/meshes/ee/openarmx_hand/visual/hand.dae" scale="0.001 0.001 0.001"/>
      </geometry>
    </visual>
    <collision name="openarmx_left_hand_collision">
      <origin rpy="0.0 0.0 0.0" xyz="0.0 0.0 -0.6585"/>
      <geometry>
        <mesh filename="package://openarmx_description/meshes/ee/openarmx_hand/collision/hand.stl" scale="0.001 0.001 0.001"/>
      </geometry>
    </collision>
    <inertial>
      <origin rpy="0 0 0" xyz="0.0 0.002 0.03"/>
      <mass value="0.35"/>
      <inertia ixx="0.0002473" ixy="1e-06" ixz="1e-06" iyy="1.763e-05" iyz="1e-06" izz="0.0002521"/>
    </inertial>
  </link>
  <!-- <link name="${ee_prefix}hand"/> -->
  <!-- <joint name="${ee_prefix}hand_joint" type="fixed"> -->
  <joint name="left_openarmx_hand_joint" type="fixed">
    <parent link="openarmx_left_link7"/>
    <child link="openarmx_left_hand"/>
    <origin rpy="0 0 0" xyz="0 -0.0 0.1001"/>
  </joint>
  <!-- Define the hand_tcp frame -->
  <link name="openarmx_left_hand_tcp"/>
  <joint name="openarmx_left_hand_tcp_joint" type="fixed">
    <origin rpy="0 0 0" xyz="0 -0.0 0.08"/>
    <parent link="openarmx_left_hand"/>
    <child link="openarmx_left_hand_tcp"/>
  </joint>
  <link name="openarmx_left_left_finger">
    <visual name="openarmx_left_left_finger_visual">
      <origin rpy="0.0 0.0 0.0" xyz="0.0 -0.05 -0.673001"/>
      <geometry>
        <mesh filename="package://openarmx_description/meshes/ee/openarmx_hand/visual/finger.dae" scale="0.001 0.001 0.001"/>
      </geometry>
    </visual>
    <collision name="openarmx_left_left_finger_collision">
      <origin rpy="0.0 0.0 0.0" xyz="0.0 -0.05 -0.673001"/>
      <geometry>
        <mesh filename="package://openarmx_description/meshes/ee/openarmx_hand/collision/finger.stl" scale="0.001 0.001 0.001"/>
      </geometry>
    </collision>
    <inertial>
      <origin rpy="0 0 0" xyz="0.0064528 0.01702 0.0219685"/>
      <mass value="0.03602545343277134"/>
      <inertia ixx="2.3749999999999997e-06" ixy="0" ixz="0" iyy="2.3749999999999997e-06" iyz="0" izz="7.5e-07"/>
    </inertial>
  </link>
  <link name="openarmx_left_right_finger">
    <visual name="openarmx_left_right_finger_visual">
      <origin rpy="0.0 0.0 0.0" xyz="0.0 0.05 -0.673001"/>
      <geometry>
        <mesh filename="package://openarmx_description/meshes/ee/openarmx_hand/visual/finger.dae" scale="0.001 -0.001 0.001"/>
      </geometry>
    </visual>
    <collision name="openarmx_left_right_finger_collision">
      <origin rpy="0.0 0.0 0.0" xyz="0.0 0.05 -0.673001"/>
      <geometry>
        <mesh filename="package://openarmx_description/meshes/ee/openarmx_hand/collision/finger.stl" scale="0.001 -0.001 0.001"/>
      </geometry>
    </collision>
    <inertial>
      <origin rpy="0 0 0" xyz="0.0064528 -0.01702 0.0219685"/>
      <mass value="0.03602545343277134"/>
      <inertia ixx="2.3749999999999997e-06" ixy="0" ixz="0" iyy="2.3749999999999997e-06" iyz="0" izz="7.5e-07"/>
    </inertial>
  </link>
  <joint name="openarmx_left_finger_joint1" type="prismatic">
    <parent link="openarmx_left_hand"/>
    <child link="openarmx_left_right_finger"/>
    <origin rpy="0 0 0" xyz="0 -0.006 0.015"/>
    <axis xyz="0 -1 0"/>
    <limit effort="333" lower="0.0" upper="0.044" velocity="10.0"/>
  </joint>
  <joint name="openarmx_left_finger_joint2" type="prismatic">
    <parent link="openarmx_left_hand"/>
    <child link="openarmx_left_left_finger"/>
    <origin rpy="0 0 0" xyz="0 0.006 0.015"/>
    <axis xyz="0 1 0"/>
    <limit effort="333" lower="0.0" upper="0.044" velocity="10.0"/>
    <mimic joint="openarmx_left_finger_joint1"/>
  </joint>
  <link name="openarmx_right_hand">
    <visual name="openarmx_right_hand_visual">
      <origin rpy="0.0 0.0 0.0" xyz="0.0 0.0 -0.6585"/>
      <geometry>
        <mesh filename="package://openarmx_description/meshes/ee/openarmx_hand/visual/hand.dae" scale="0.001 0.001 0.001"/>
      </geometry>
    </visual>
    <collision name="openarmx_right_hand_collision">
      <origin rpy="0.0 0.0 0.0" xyz="0.0 0.0 -0.6585"/>
      <geometry>
        <mesh filename="package://openarmx_description/meshes/ee/openarmx_hand/collision/hand.stl" scale="0.001 0.001 0.001"/>
      </geometry>
    </collision>
    <inertial>
      <origin rpy="0 0 0" xyz="0.0 0.002 0.03"/>
      <mass value="0.35"/>
      <inertia ixx="0.0002473" ixy="1e-06" ixz="1e-06" iyy="1.763e-05" iyz="1e-06" izz="0.0002521"/>
    </inertial>
  </link>
  <!-- <link name="${ee_prefix}hand"/> -->
  <!-- <joint name="${ee_prefix}hand_joint" type="fixed"> -->
  <joint name="right_openarmx_hand_joint" type="fixed">
    <parent link="openarmx_right_link7"/>
    <child link="openarmx_right_hand"/>
    <origin rpy="0 0 0" xyz="0 -0.0 0.1001"/>
  </joint>
  <!-- Define the hand_tcp frame -->
  <link name="openarmx_right_hand_tcp"/>
  <joint name="openarmx_right_hand_tcp_joint" type="fixed">
    <origin rpy="0 0 0" xyz="0 -0.0 0.08"/>
    <parent link="openarmx_right_hand"/>
    <child link="openarmx_right_hand_tcp"/>
  </joint>
  <link name="openarmx_right_left_finger">
    <visual name="openarmx_right_left_finger_visual">
      <origin rpy="0.0 0.0 0.0" xyz="0.0 -0.05 -0.673001"/>
      <geometry>
        <mesh filename="package://openarmx_description/meshes/ee/openarmx_hand/visual/finger.dae" scale="0.001 0.001 0.001"/>
      </geometry>
    </visual>
    <collision name="openarmx_right_left_finger_collision">
      <origin rpy="0.0 0.0 0.0" xyz="0.0 -0.05 -0.673001"/>
      <geometry>
        <mesh filename="package://openarmx_description/meshes/ee/openarmx_hand/collision/finger.stl" scale="0.001 0.001 0.001"/>
      </geometry>
    </collision>
    <inertial>
      <origin rpy="0 0 0" xyz="0.0064528 0.01702 0.0219685"/>
      <mass value="0.03602545343277134"/>
      <inertia ixx="2.3749999999999997e-06" ixy="0" ixz="0" iyy="2.3749999999999997e-06" iyz="0" izz="7.5e-07"/>
    </inertial>
  </link>
  <link name="openarmx_right_right_finger">
    <visual name="openarmx_right_right_finger_visual">
      <origin rpy="0.0 0.0 0.0" xyz="0.0 0.05 -0.673001"/>
      <geometry>
        <mesh filename="package://openarmx_description/meshes/ee/openarmx_hand/visual/finger.dae" scale="0.001 -0.001 0.001"/>
      </geometry>
    </visual>
    <collision name="openarmx_right_right_finger_collision">
      <origin rpy="0.0 0.0 0.0" xyz="0.0 0.05 -0.673001"/>
      <geometry>
        <mesh filename="package://openarmx_description/meshes/ee/openarmx_hand/collision/finger.stl" scale="0.001 -0.001 0.001"/>
      </geometry>
    </collision>
    <inertial>
      <origin rpy="0 0 0" xyz="0.0064528 -0.01702 0.0219685"/>
      <mass value="0.03602545343277134"/>
      <inertia ixx="2.3749999999999997e-06" ixy="0" ixz="0" iyy="2.3749999999999997e-06" iyz="0" izz="7.5e-07"/>
    </inertial>
  </link>
  <joint name="openarmx_right_finger_joint1" type="prismatic">
    <parent link="openarmx_right_hand"/>
    <child link="openarmx_right_right_finger"/>
    <origin rpy="0 0 0" xyz="0 -0.006 0.015"/>
    <axis xyz="0 -1 0"/>
    <limit effort="333" lower="0.0" upper="0.044" velocity="10.0"/>
  </joint>
  <joint name="openarmx_right_finger_joint2" type="prismatic">
    <parent link="openarmx_right_hand"/>
    <child link="openarmx_right_left_finger"/>
    <origin rpy="0 0 0" xyz="0 0.006 0.015"/>
    <axis xyz="0 1 0"/>
    <limit effort="333" lower="0.0" upper="0.044" velocity="10.0"/>
    <mimic joint="openarmx_right_finger_joint1"/>
  </joint>
</robot>
